2025-04-04 21:16:01,495 - app_init - INFO - Application initialized successfully
2025-04-04 21:16:01,495 - app_init - INFO - Application initialized successfully
2025-04-04 21:16:04,613 - asyncio - DEBUG - Using proactor: IocpProactor
2025-04-04 21:16:04,615 - root - INFO - Searching for GoPro cameras (attempt 1/3)...
2025-04-04 21:16:04,800 - root - INFO - Discovered GoPro: C3531324882703._gopro-web._tcp.local. at 172.27.103.51
2025-04-04 21:16:04,804 - urllib3.connectionpool - DEBUG - Starting new HTTP connection (1): 172.27.103.51:8080
2025-04-04 21:16:09,829 - root - WARNING - USB connection check failed for camera C3531324882703._gopro-web._tcp.local. at 172.27.103.51
2025-04-04 21:16:09,829 - root - INFO - Discovered GoPro: C3531325002143._gopro-web._tcp.local. at 172.21.143.51
2025-04-04 21:16:09,829 - urllib3.connectionpool - DEBUG - Starting new HTTP connection (1): 172.21.143.51:8080
2025-04-04 21:16:14,870 - root - WARNING - USB connection check failed for camera C3531325002143._gopro-web._tcp.local. at 172.21.143.51
2025-04-04 21:16:19,617 - root - WARNING - No devices found on attempt 1, retrying...
2025-04-04 21:16:21,630 - asyncio - DEBUG - Using proactor: IocpProactor
2025-04-04 21:16:21,632 - root - INFO - Searching for GoPro cameras (attempt 2/3)...
2025-04-04 21:16:21,736 - root - INFO - Discovered GoPro: C3531324882703._gopro-web._tcp.local. at 172.27.103.51
2025-04-04 21:16:21,736 - urllib3.connectionpool - DEBUG - Starting new HTTP connection (1): 172.27.103.51:8080
2025-04-04 21:16:26,754 - root - WARNING - USB connection check failed for camera C3531324882703._gopro-web._tcp.local. at 172.27.103.51
2025-04-04 21:16:26,754 - root - INFO - Discovered GoPro: C3531325002143._gopro-web._tcp.local. at 172.21.143.51
2025-04-04 21:16:26,754 - urllib3.connectionpool - DEBUG - Starting new HTTP connection (1): 172.21.143.51:8080
2025-04-04 21:16:31,771 - root - WARNING - USB connection check failed for camera C3531325002143._gopro-web._tcp.local. at 172.21.143.51
2025-04-04 21:16:36,637 - root - WARNING - No devices found on attempt 2, retrying...
2025-04-04 21:16:38,639 - asyncio - DEBUG - Using proactor: IocpProactor
2025-04-04 21:16:38,639 - root - INFO - Searching for GoPro cameras (attempt 3/3)...
2025-04-04 21:16:39,770 - zeroconf - WARNING - Error with socket 2184 (('172.21.143.55', 5353))): [WinError 59] An unexpected network error occurred
Traceback (most recent call last):
  File "C:\Users\jan\AppData\Local\Programs\Python\Python312\Lib\asyncio\proactor_events.py", line 523, in _loop_writing
    fut.result()
  File "C:\Users\jan\AppData\Local\Programs\Python\Python312\Lib\asyncio\windows_events.py", line 803, in _poll
    value = callback(transferred, key, ov)
            ^^^^^^^^^^^^^^^^^^^^^^^^^^^^^^
  File "C:\Users\jan\AppData\Local\Programs\Python\Python312\Lib\asyncio\windows_events.py", line 462, in finish_socket_func
    return ov.getresult()
           ^^^^^^^^^^^^^^
OSError: [WinError 59] An unexpected network error occurred
2025-04-04 21:16:39,804 - zeroconf - WARNING - Error with socket 2016 (('172.27.103.55', 5353))): [WinError 59] An unexpected network error occurred
Traceback (most recent call last):
  File "C:\Users\jan\AppData\Local\Programs\Python\Python312\Lib\asyncio\proactor_events.py", line 523, in _loop_writing
    fut.result()
  File "C:\Users\jan\AppData\Local\Programs\Python\Python312\Lib\asyncio\windows_events.py", line 803, in _poll
    value = callback(transferred, key, ov)
            ^^^^^^^^^^^^^^^^^^^^^^^^^^^^^^
  File "C:\Users\jan\AppData\Local\Programs\Python\Python312\Lib\asyncio\windows_events.py", line 462, in finish_socket_func
    return ov.getresult()
           ^^^^^^^^^^^^^^
OSError: [WinError 59] An unexpected network error occurred
