2025-03-27 19:01:18,878 - asyncio - DEBUG - Using proactor: IocpProactor
2025-03-27 19:01:18,880 - root - INFO - Searching for GoPro cameras (attempt 1/3)...
2025-03-27 19:01:18,972 - root - INFO - Discovered GoPro: C3531325002143._gopro-web._tcp.local. at 172.21.143.51
2025-03-27 19:01:19,006 - urllib3.connectionpool - DEBUG - Starting new HTTP connection (1): 172.21.143.51:8080
2025-03-27 19:01:19,068 - urllib3.connectionpool - DEBUG - http://172.21.143.51:8080 "GET /gopro/camera/state HTTP/1.1" 200 1579
2025-03-27 19:01:33,881 - root - INFO - Found 1 GoPro devices.
2025-03-27 19:01:33,884 - root - INFO - Found the following GoPro devices:
2025-03-27 19:01:33,884 - root - INFO - Name: C3531325002143._gopro-web._tcp.local., IP: 172.21.143.51
2025-03-27 19:01:33,888 - root - INFO - Cache updated successfully with 5 devices.
2025-03-27 19:01:33,889 - root - INFO - Resetting USB control on camera 172.21.143.51 (attempt 1/3)
2025-03-27 19:01:33,892 - urllib3.connectionpool - DEBUG - Starting new HTTP connection (1): 172.21.143.51:8080
2025-03-27 19:01:33,973 - urllib3.connectionpool - DEBUG - http://172.21.143.51:8080 "GET /gopro/camera/control/wired_usb?p=0 HTTP/1.1" 200 3
2025-03-27 19:01:33,974 - root - INFO - USB control disabled on camera 172.21.143.51.
2025-03-27 19:01:35,978 - urllib3.connectionpool - DEBUG - Starting new HTTP connection (1): 172.21.143.51:8080
2025-03-27 19:01:36,064 - urllib3.connectionpool - DEBUG - http://172.21.143.51:8080 "GET /gopro/camera/control/wired_usb?p=1 HTTP/1.1" 200 3
2025-03-27 19:01:36,065 - root - INFO - USB control enabled on camera 172.21.143.51.
2025-03-27 19:01:36,066 - urllib3.connectionpool - DEBUG - Starting new HTTP connection (1): 172.21.143.51:8080
2025-03-27 19:01:36,102 - urllib3.connectionpool - DEBUG - http://172.21.143.51:8080 "GET /gopro/camera/state HTTP/1.1" 200 1579
2025-03-27 19:01:36,103 - root - INFO - USB control successfully reset for camera 172.21.143.51
2025-03-27 19:01:38,117 - asyncio - DEBUG - Using proactor: IocpProactor
2025-03-27 19:01:38,121 - root - INFO - Searching for GoPro cameras (attempt 1/3)...
2025-03-27 19:01:38,934 - root - INFO - Discovered GoPro: C3531325002143._gopro-web._tcp.local. at 172.21.143.51
2025-03-27 19:01:38,936 - urllib3.connectionpool - DEBUG - Starting new HTTP connection (1): 172.21.143.51:8080
2025-03-27 19:01:38,970 - urllib3.connectionpool - DEBUG - http://172.21.143.51:8080 "GET /gopro/camera/state HTTP/1.1" 200 1579
2025-03-27 19:01:52,185 - zeroconf - WARNING - Error with socket 1252 (('172.21.143.55', 5353))): [WinError 59] An unexpected network error occurred
Traceback (most recent call last):
  File "C:\Program Files\WindowsApps\PythonSoftwareFoundation.Python.3.13_3.13.752.0_x64__qbz5n2kfra8p0\Lib\asyncio\proactor_events.py", line 520, in _loop_writing
    fut.result()
    ~~~~~~~~~~^^
  File "C:\Program Files\WindowsApps\PythonSoftwareFoundation.Python.3.13_3.13.752.0_x64__qbz5n2kfra8p0\Lib\asyncio\windows_events.py", line 804, in _poll
    value = callback(transferred, key, ov)
  File "C:\Program Files\WindowsApps\PythonSoftwareFoundation.Python.3.13_3.13.752.0_x64__qbz5n2kfra8p0\Lib\asyncio\windows_events.py", line 463, in finish_socket_func
    return ov.getresult()
           ~~~~~~~~~~~~^^
OSError: [WinError 59] An unexpected network error occurred
2025-03-27 19:01:53,123 - root - INFO - Found 1 GoPro devices.
2025-03-27 19:01:53,126 - root - INFO - Found 1 cameras
2025-03-27 19:01:53,130 - urllib3.connectionpool - DEBUG - Starting new HTTP connection (1): 172.21.143.51:8080
2025-03-27 19:01:58,144 - root - ERROR - Error checking if camera is prime: HTTPConnectionPool(host='172.21.143.51', port=8080): Max retries exceeded with url: /gp/gpControl/info (Caused by ConnectTimeoutError(<urllib3.connection.HTTPConnection object at 0x0000017901000DD0>, 'Connection to 172.21.143.51 timed out. (connect timeout=5)'))
